<?xml version="1.0" ?>
<!-- =================================================================================== -->
<!-- |    This document was autogenerated by xacro from lwr_ahand_init.xacro           | -->
<!-- |    EDITING THIS FILE BY HAND IS NOT RECOMMENDED                                 | -->
<!-- =================================================================================== -->
<robot name="lwr_ahand" xmlns:xacro="http://ros.org/wiki/xacro">
  <material name="Kuka/DarkGrey">
    <color rgba="0.3 0.3 0.3 1.0"/>
  </material>
  <material name="Kuka/LightGrey">
    <color rgba="0.8 0.8 0.8 1.0"/>
  </material>
  <material name="Kuka/Red">
    <color rgba="0.3 0.3 0.3 1.0"/>
  </material>
  <material name="Kuka/Black">
    <color rgba="0 0 0 1.0"/>
  </material>
  <material name="Kuka/Orange">
    <color rgba="1.0 0.487 0 1.0"/>
  </material>
  <material name="Kuka/Silver">
    <color rgba="1.0 1.0 1.0 1.0"/>
  </material>
  <material name="Kuka/Grey">
    <color rgba="0.7 0.7 0.7 1.0"/>
  </material>
  <material name="Kuka/Blue">
    <color rgba="0.0 0.0 0.8 1.0"/>
  </material>
  <link name="world"/>
  <joint name="world_lwr_base_joint" type="fixed">
    <origin rpy="0 0 0" xyz="0 0 0"/>
    <origin rpy="0 0 0" xyz="0 0 0"/>
    <parent link="world"/>
    <child link="lwr_base_link"/>
  </joint>
  <link name="lwr_base_link">
    <inertial>
      <mass value="2.0"/>
      <origin xyz="0 0 0.055"/>
      <inertia ixx="0.00381666666667" ixy="0" ixz="0" iyy="0.0036" iyz="0" izz="0.00381666666667"/>
    </inertial>
    <visual>
      <origin rpy="0 0 3.14159265359" xyz="0 0 0"/>
      <geometry>
        <mesh filename="package://lwr_description/meshes/arm_base.dae"/>
      </geometry>
      <material name="Kuka/Orange"/>
    </visual>
    <collision>
      <origin rpy="0 0 3.14159265359" xyz="0 0 0.055"/>
      <geometry>
        <!-- <mesh filename="package://lwr_description/meshes/convex/arm_base_convex.stl"/> -->
        <cylinder length="0.11" radius="0.07"/>
      </geometry>
    </collision>
  </link>
  <joint name="lwr_0_joint" type="revolute">
    <origin rpy="0 0 0" xyz="0 0 0.11"/>
    <axis xyz="0 0 1"/>
    <limit effort="204" lower="-2.96705972839" upper="2.96705972839" velocity="5.75958653158"/>
    <safety_controller k_position="30" k_velocity="30" soft_lower_limit="-2.93215314335" soft_upper_limit="2.93215314335"/>
    <dynamics damping="1.0" friction="10.0"/>
    <parent link="lwr_base_link"/>
    <child link="lwr_1_link"/>
  </joint>
  <link name="lwr_1_link">
    <inertial>
      <mass value="2.0"/>
      <origin rpy="0 0 0" xyz="0 -0.06 0.130"/>
      <inertia ixx="0.0136666666667" ixy="0" ixz="0" iyy="0.003" iyz="0" izz="0.0118666666667"/>
    </inertial>
    <visual>
      <origin rpy="0 0 3.14159265359" xyz="0 0 -0.008"/>
      <geometry>
        <mesh filename="package://lwr_description/meshes/arm_segment_a.dae"/>
      </geometry>
      <material name="Kuka/Orange"/>
    </visual>
    <collision>
      <origin rpy="0 0 0" xyz="0 0 0.0"/>
      <geometry>
        <!--mesh filename="package://lwr_description/meshes/convex/arm_segment_a_convex.stl"/-->
        <sphere radius="0.07"/>
      </geometry>
    </collision>
    <collision>
      <origin rpy="0 0 0" xyz="0 0.06 0.2"/>
      <geometry>
        <sphere radius="0.07"/>
      </geometry>
    </collision>
    <collision>
      <origin rpy="-0.291 0 0" xyz="0 0.03 0.1"/>
      <geometry>
        <cylinder length="0.208" radius="0.07"/>
      </geometry>
    </collision>
  </link>
  <joint name="lwr_1_joint" type="revolute">
    <origin rpy="0 0 0" xyz="0 0 0.2005"/>
    <axis xyz="0 -1 0"/>
    <limit effort="306" lower="-2.09439510239" upper="2.09439510239" velocity="5.75958653158"/>
    <safety_controller k_position="30" k_velocity="30" soft_lower_limit="-2.05948851735" soft_upper_limit="2.05948851735"/>
    <dynamics damping="1.0" friction="10.0"/>
    <parent link="lwr_1_link"/>
    <child link="lwr_2_link"/>
  </joint>
  <link name="lwr_2_link">
    <inertial>
      <mass value="2.0"/>
      <origin rpy="0 0 0" xyz="0 0.06 0.07"/>
      <inertia ixx="0.0136666666667" ixy="0" ixz="0" iyy="0.003" iyz="0" izz="0.0118666666667"/>
    </inertial>
    <visual>
      <origin rpy="3.14159265359 0 3.14159265359" xyz="0 0 0.1915"/>
      <geometry>
        <mesh filename="package://lwr_description/meshes/arm_segment_b.dae"/>
      </geometry>
      <material name="Kuka/Orange"/>
    </visual>
    <collision>
      <origin rpy="0 0 0" xyz="0 0 0.2"/>
      <geometry>
        <!--mesh filename="package://lwr_description/meshes/convex/arm_segment_b_convex.stl"/-->
        <sphere radius="0.07"/>
      </geometry>
    </collision>
    <collision>
      <origin rpy="0 0 0" xyz="0 -0.06 0.0"/>
      <geometry>
        <sphere radius="0.07"/>
      </geometry>
    </collision>
    <collision>
      <origin rpy="-0.291 0 0" xyz="0 -0.03 0.1"/>
      <geometry>
        <cylinder length="0.208" radius="0.07"/>
      </geometry>
    </collision>
  </link>
  <joint name="lwr_2_joint" type="revolute">
    <origin rpy="0 0 0" xyz="0 0 0.20"/>
    <axis xyz="0 0 1"/>
    <limit effort="204" lower="-2.96705972839" upper="2.96705972839" velocity="6.80678408278"/>
    <safety_controller k_position="30" k_velocity="30" soft_lower_limit="-2.93215314335" soft_upper_limit="2.93215314335"/>
    <dynamics damping="1.0" friction="10.0"/>
    <parent link="lwr_2_link"/>
    <child link="lwr_3_link"/>
  </joint>
  <link name="lwr_3_link">
    <inertial>
      <mass value="2.0"/>
      <origin rpy="0 0 0" xyz="0 0.06 0.130"/>
      <inertia ixx="0.0136666666667" ixy="0" ixz="0" iyy="0.003" iyz="0" izz="0.0118666666667"/>
    </inertial>
    <visual>
      <origin rpy="0 0 0" xyz="0 0 -0.008"/>
      <geometry>
        <mesh filename="package://lwr_description/meshes/arm_segment_a.dae"/>
      </geometry>
      <material name="Kuka/Orange"/>
    </visual>
    <collision>
      <origin rpy="0 0 0" xyz="0 0 0.0"/>
      <geometry>
        <!--mesh filename="package://lwr_description/meshes/convex/arm_segment_a_convex.stl"/-->
        <sphere radius="0.07"/>
      </geometry>
    </collision>
    <collision>
      <origin rpy="0 0 0" xyz="0 -0.06 0.2"/>
      <geometry>
        <sphere radius="0.07"/>
      </geometry>
    </collision>
    <collision>
      <origin rpy="0.291 0 0" xyz="0 -0.03 0.1"/>
      <geometry>
        <cylinder length="0.208" radius="0.07"/>
      </geometry>
    </collision>
  </link>
  <joint name="lwr_3_joint" type="revolute">
    <origin rpy="0 0 0" xyz="0 0 0.20"/>
    <axis xyz="0 1 0"/>
    <limit effort="306" lower="-2.09439510239" upper="2.09439510239" velocity="6.80678408278"/>
    <safety_controller k_position="30" k_velocity="30" soft_lower_limit="-2.05948851735" soft_upper_limit="2.05948851735"/>
    <dynamics damping="1.0" friction="10.0"/>
    <parent link="lwr_3_link"/>
    <child link="lwr_4_link"/>
  </joint>
  <link name="lwr_4_link">
    <inertial>
      <mass value="2.0"/>
      <origin rpy="0 0 0" xyz="0 -0.06 0.07"/>
      <inertia ixx="0.0136666666667" ixy="0" ixz="0" iyy="0.003" iyz="0" izz="0.0118666666667"/>
    </inertial>
    <visual>
      <origin rpy="0 3.14159265359 3.14159265359" xyz="0 0 0.195"/>
      <geometry>
        <mesh filename="package://lwr_description/meshes/arm_segment_b.dae"/>
      </geometry>
      <material name="Kuka/Orange"/>
    </visual>
    <collision>
      <origin rpy="0 0 0" xyz="0 0 0.2"/>
      <geometry>
        <!--mesh filename="package://lwr_description/meshes/convex/arm_segment_b_convex.stl"/-->
        <sphere radius="0.07"/>
      </geometry>
    </collision>
    <collision>
      <origin rpy="0 0 0" xyz="0 0.06 0.0"/>
      <geometry>
        <sphere radius="0.07"/>
      </geometry>
    </collision>
    <collision>
      <origin rpy="0.291 0 0" xyz="0 0.03 0.1"/>
      <geometry>
        <cylinder length="0.208" radius="0.07"/>
      </geometry>
    </collision>
  </link>
  <joint name="lwr_4_joint" type="revolute">
    <origin rpy="0 0 0" xyz="0 0 0.20"/>
    <axis xyz="0 0 1"/>
    <limit effort="204" lower="-2.96705972839" upper="2.96705972839" velocity="6.80678408278"/>
    <safety_controller k_position="30" k_velocity="30" soft_lower_limit="-2.93215314335" soft_upper_limit="2.93215314335"/>
    <dynamics damping="1.0" friction="10.0"/>
    <parent link="lwr_4_link"/>
    <child link="lwr_5_link"/>
  </joint>
  <link name="lwr_5_link">
    <inertial>
      <mass value="2.0"/>
      <origin rpy="0 0 0" xyz="0 0 0.124"/>
      <inertia ixx="0.0126506666667" ixy="0" ixz="0" iyy="0.003" iyz="0" izz="0.0108506666667"/>
    </inertial>
    <visual>
      <origin rpy="0 0 3.14159265359" xyz="0 0 -0.008"/>
      <geometry name="lwr_5_geom">
        <mesh filename="package://lwr_description/meshes/arm_segment_last.dae"/>
      </geometry>
      <material name="Kuka/Orange"/>
    </visual>
    <collision>
      <origin rpy="0 0 0" xyz="0 0 0.0"/>
      <geometry>
        <!--mesh filename="package://lwr_description/meshes/convex/arm_segment_last_convex.stl"/-->
        <sphere radius="0.07"/>
      </geometry>
    </collision>
    <collision>
      <origin rpy="0 0 0" xyz="0 0.04 0.19"/>
      <geometry>
        <sphere radius="0.07"/>
      </geometry>
    </collision>
    <collision>
      <origin rpy="-0.207 0 0" xyz="0 0.02 0.095"/>
      <geometry>
        <cylinder length="0.198" radius="0.07"/>
      </geometry>
    </collision>
  </link>
  <joint name="lwr_5_joint" type="revolute">
    <origin rpy="0 0 0" xyz="0 0 0.19"/>
    <axis xyz="0 -1 0"/>
    <limit effort="306" lower="-2.09439510239" upper="2.09439510239" velocity="9.42477796077"/>
    <safety_controller k_position="30" k_velocity="30" soft_lower_limit="-2.05948851735" soft_upper_limit="2.05948851735"/>
    <dynamics damping="1.0" friction="10.0"/>
    <parent link="lwr_5_link"/>
    <child link="lwr_6_link"/>
  </joint>
  <link name="lwr_6_link">
    <inertial>
      <mass value="0.2"/>
      <origin rpy="0 0 0" xyz="0 0 0.0625"/>
      <inertia ixx="0.000520833333333" ixy="0" ixz="0" iyy="0.000520833333333" iyz="0" izz="0.000520833333333"/>
    </inertial>
    <visual>
      <origin rpy="0 0 3.14159265359" xyz="0 0 -0.005"/>
      <geometry>
        <mesh filename="package://lwr_description/meshes/arm_wrist.dae"/>
      </geometry>
      <material name="Kuka/Grey"/>
    </visual>
    <collision>
      <origin rpy="0 0 3.14159265359" xyz="0 0 0"/>
      <geometry>
        <mesh filename="package://lwr_description/meshes/convex/arm_wrist_convex.stl"/>
      </geometry>
    </collision>
  </link>
  <joint name="lwr_6_joint" type="revolute">
    <origin rpy="0 0 0" xyz="0 0 0.078"/>
    <axis xyz="0 0 1"/>
    <limit effort="204" lower="-2.96705972839" upper="2.96705972839" velocity="9.42477796077"/>
    <safety_controller k_position="30" k_velocity="30" soft_lower_limit="-2.93215314335" soft_upper_limit="2.93215314335"/>
    <dynamics damping="1.0" friction="10.0"/>
    <parent link="lwr_6_link"/>
    <child link="lwr_7_link"/>
  </joint>
  <link name="lwr_7_link">
    <inertial>
      <mass value="0.2"/>
      <origin xyz="0 0 0"/>
      <inertia ixx="0.0333333333333" ixy="0" ixz="0" iyy="0.0333333333333" iyz="0" izz="0.0333333333333"/>
    </inertial>
    <visual>
      <origin rpy="0 0 3.14159265359" xyz="0 0 -0.005"/>
      <geometry>
        <mesh filename="package://lwr_description/meshes/link_7.STL"/>
      </geometry>
      <material name="Kuka/DarkGrey"/>
    </visual>
    <collision>
      <origin rpy="0 0 3.14159265359" xyz="0 0 0"/>
      <geometry>
        <cylinder length="0.05" radius="0.04"/>
      </geometry>
    </collision>
  </link>
  <gazebo>
    <plugin filename="libgazebo_ros_control.so" name="gazebo_ros_control">
      <robotNamespace>lwr</robotNamespace>
    </plugin>
  </gazebo>
  <gazebo reference="lwr_base_link">
    <gravity>true</gravity>
    <!--material>Gazebo/Orange</material-->
  </gazebo>
  <gazebo reference="lwr_1_link">
    <gravity>true</gravity>
    <!-- <material>Gazebo/Orange</material> -->
  </gazebo>
  <gazebo reference="lwr_2_link">
    <gravity>true</gravity>
    <!-- <material>Gazebo/Orange</material> -->
  </gazebo>
  <gazebo reference="lwr_3_link">
    <gravity>true</gravity>
    <!-- <material>Gazebo/Orange</material> -->
  </gazebo>
  <gazebo reference="lwr_4_link">
    <gravity>true</gravity>
    <!--material>Gazebo/Orange</material-->
  </gazebo>
  <gazebo reference="lwr_5_link">
    <gravity>true</gravity>
    <!--material>Gazebo/Orange</material-->
  </gazebo>
  <gazebo reference="lwr_6_link">
    <gravity>true</gravity>
    <!--material>Gazebo/Orange</material-->
  </gazebo>
  <gazebo reference="lwr_7_link">
    <gravity>true</gravity>
    <material>Gazebo/Grey</material>
  </gazebo>
  <transmission name="lwr_0_trans">
    <type>transmission_interface/SimpleTransmission</type>
    <joint name="lwr_0_joint">
      <hardwareInterface>EffortJointInterface</hardwareInterface>
    </joint>
    <actuator name="lwr_0_motor">
      <hardwareInterface>EffortJointInterface</hardwareInterface>
      <mechanicalReduction>1</mechanicalReduction>
    </actuator>
  </transmission>
  <transmission name="lwr_1_trans">
    <type>transmission_interface/SimpleTransmission</type>
    <joint name="lwr_1_joint">
      <hardwareInterface>EffortJointInterface</hardwareInterface>
    </joint>
    <actuator name="lwr_1_motor">
      <hardwareInterface>EffortJointInterface</hardwareInterface>
      <mechanicalReduction>1</mechanicalReduction>
    </actuator>
  </transmission>
  <transmission name="lwr_2_trans">
    <type>transmission_interface/SimpleTransmission</type>
    <joint name="lwr_2_joint">
      <hardwareInterface>EffortJointInterface</hardwareInterface>
    </joint>
    <actuator name="lwr_2_motor">
      <hardwareInterface>EffortJointInterface</hardwareInterface>
      <mechanicalReduction>1</mechanicalReduction>
    </actuator>
  </transmission>
  <transmission name="lwr_3_trans">
    <type>transmission_interface/SimpleTransmission</type>
    <joint name="lwr_3_joint">
      <hardwareInterface>EffortJointInterface</hardwareInterface>
    </joint>
    <actuator name="lwr_3_motor">
      <hardwareInterface>EffortJointInterface</hardwareInterface>
      <mechanicalReduction>1</mechanicalReduction>
    </actuator>
  </transmission>
  <transmission name="lwr_4_trans">
    <type>transmission_interface/SimpleTransmission</type>
    <joint name="lwr_4_joint">
      <hardwareInterface>EffortJointInterface</hardwareInterface>
    </joint>
    <actuator name="lwr_4_motor">
      <hardwareInterface>EffortJointInterface</hardwareInterface>
      <mechanicalReduction>1</mechanicalReduction>
    </actuator>
  </transmission>
  <transmission name="lwr_5_trans">
    <type>transmission_interface/SimpleTransmission</type>
    <joint name="lwr_5_joint">
      <hardwareInterface>EffortJointInterface</hardwareInterface>
    </joint>
    <actuator name="lwr_5_motor">
      <hardwareInterface>EffortJointInterface</hardwareInterface>
      <mechanicalReduction>1</mechanicalReduction>
    </actuator>
  </transmission>
  <transmission name="lwr_6_trans">
    <type>transmission_interface/SimpleTransmission</type>
    <joint name="lwr_6_joint">
      <hardwareInterface>EffortJointInterface</hardwareInterface>
    </joint>
    <actuator name="lwr_6_motor">
      <hardwareInterface>EffortJointInterface</hardwareInterface>
      <mechanicalReduction>1</mechanicalReduction>
    </actuator>
  </transmission>
  <joint name="ahand_base_joint" type="fixed">
    <parent link="lwr_7_link"/>
    <child link="ahand_palm_link"/>
    <origin rpy="0 0 0" xyz="0.0 0 0.09"/>
  </joint>
  <link name="ahand_palm_link">
    <inertial>
      <origin xyz="-0.01 0 -0.05"/>
      <!--origin xyz="-0.01 0 -0.05"/-->
      <inertia ixx="0.00184605916667" ixy="0" ixz="0" iyy="0.00112558666667" iyz="0" izz="0.00103097916667"/>
      <mass value="1.1644"/>
    </inertial>
    <visual>
      <origin rpy="3.14159265359 0 0" xyz="-0.0282 -0.057 -0.095"/>
      <!-- DONE -->
      <material name="all">
        <color rgba="0.1 0.1 0.1 0.5"/>
      </material>
      <geometry>
        <mesh filename="package://allegro_hand_description/meshes/allegro_palm_left.dae"/>
      </geometry>
    </visual>
    <collision>
      <origin rpy="3.14159265359 0 0" xyz="-0.0282 -0.057 -0.095"/>
      <!-- DONE -->
      <geometry>
        <mesh filename="package://allegro_hand_description/meshes/allegro_palm_left.dae"/>
      </geometry>
    </collision>
  </link>
  <joint name="ahand_palm_surface_joint" type="fixed">
    <parent link="ahand_palm_link"/>
    <child link="ahand_palm_surface_link"/>
    <origin rpy="0 0 0" xyz="0 0 0.08"/>
    <limit effort="5" lower="0" upper="3.14159265359" velocity="5.0"/>
    <dynamics damping="0.002" friction="0.08"/>
  </joint>
  <link name="ahand_palm_surface_link">
    <inertial>
      <mass value="0.000001"/>
      <inertia ixx="0.000001" ixy="0.0" ixz="0.0" iyy="0.000001" iyz="0.0" izz="0.000001"/>
    </inertial>
  </link>
  <joint name="ahand_grasp_joint" type="fixed">
    <parent link="ahand_palm_link"/>
    <child link="ahand_grasp_link"/>
    <origin rpy="0 0 0" xyz="0 0 0.12"/>
    <limit effort="5" lower="0" upper="3.14159265359" velocity="5.0"/>
    <dynamics damping="0.002" friction="0.08"/>
  </joint>
  <link name="ahand_grasp_link">
    <inertial>
      <mass value="0.000001"/>
      <inertia ixx="0.000001" ixy="0.0" ixz="0.0" iyy="0.000001" iyz="0.0" izz="0.000001"/>
    </inertial>
  </link>
  <joint name="f1_dof0_joint" type="revolute">
    <parent link="ahand_palm_link"/>
    <child link="f1_dof0_link"/>
    <origin rpy="0.0873 0 0" xyz="0 -0.044981 -0.002298"/>
    <axis xyz="0 0 1"/>
    <limit effort="100" lower="-0.469999993522" upper="0.469999993522" velocity="100"/>
    <dynamics damping="0.002" friction="0.08"/>
  </joint>
  <link name="f1_dof0_link">
    <inertial>
      <origin xyz="0.00 0 0.01"/>
      <inertia ixx="9.39583333333e-07" ixy="0" ixz="0" iyy="1.14583333333e-06" iyz="0" izz="9.39583333333e-07"/>
      <mass value="0.011"/>
    </inertial>
    <visual>
      <origin rpy="1.57079632679 0.0 0.0 " xyz="-0.0098 -0.012 0.0"/>
      <!-- DONE, OK -->
      <material name="all">
        <color rgba="0.1 0.1 0.1 0.5"/>
      </material>
      <geometry>
        <mesh filename="package://allegro_hand_description/meshes/allegro_fingerdof0.dae"/>
      </geometry>
    </visual>
    <collision>
      <origin rpy="1.57079632679 0.0 0.0 " xyz="-0.0098 -0.012 0.0"/>
      <!-- DONE, OK -->
      <material name="all">
        <color rgba="0.1 0.1 0.1 0.5"/>
      </material>
      <geometry>
        <mesh filename="package://allegro_hand_description/meshes/allegro_fingerdof0.dae"/>
      </geometry>
    </collision>
  </link>
  <joint name="f1_dof1_joint" type="revolute">
    <parent link="f1_dof0_link"/>
    <child link="f1_dof1_link"/>
    <origin rpy="-1.57079632679 0 0" xyz="0 0 0.0164"/>
    <axis xyz="0 0 1"/>
    <limit effort="100" lower="-0.19600000376" upper="1.60999999972" velocity="100"/>
    <dynamics damping="0.002" friction="0.08"/>
  </joint>
  <link name="f1_dof1_link">
    <inertial>
      <origin xyz="0.  -0.027 0 "/>
      <inertia ixx="2.01246833333e-05" ixy="0" ixz="0" iyy="7.10416666667e-06" iyz="0" izz="2.01246833333e-05"/>
      <mass value="0.0682"/>
    </inertial>
    <visual>
      <material name="WAMGrey">
        <color rgba="0.9 0.9 0.9 1.0"/>
      </material>
      <origin rpy="0 0 0.0" xyz="-0.0098 -0.0638 0.012"/>
      <!-- DONE -->
      <geometry>
        <mesh filename="package://allegro_hand_description/meshes/allegro_fingerdof1.dae"/>
      </geometry>
    </visual>
    <collision>
      <origin rpy="1.57079632679 0 0.0" xyz=" 0.  -0.027 0  "/>
      <geometry>
        <cylinder length="0.035" radius="0.0125"/>
      </geometry>
    </collision>
  </link>
  <joint name="f1_dof2_joint" type="revolute">
    <parent link="f1_dof1_link"/>
    <child link="f1_dof2_link"/>
    <origin rpy="0 0 -1.57079632679" xyz="0.0 -0.054 0.0"/>
    <!-- DONE -->
    <axis xyz="0 0 1"/>
    <limit effort="100" lower="-0.174000006366" upper="1.70899999672" velocity="100"/>
    <dynamics damping="0.002" friction="0.08"/>
  </joint>
  <link name="f1_dof2_link">
    <inertial>
      <origin xyz=" 0.0192 0 0 "/>
      <inertia ixx="4.1875e-06" ixy="0" ixz="0" iyy="7.033526e-06" iyz="0" izz="7.033526e-06"/>
      <mass value="0.0402"/>
    </inertial>
    <visual>
      <origin rpy="3.14159265359 0 1.57079632679" xyz="-0.0098 -0.0098 -0.012"/>
      <!-- DONE -->
      <material name="WAMGrey">
        <color rgba="0.9 0.9 0.9 0.0"/>
      </material>
      <geometry>
        <mesh filename="package://allegro_hand_description/meshes/allegro_fingerdof2.dae"/>
      </geometry>
    </visual>
    <collision>
      <origin rpy="1.57079632679 0 1.57079632679" xyz=" 0.0192 0 0 "/>
      <geometry>
        <cylinder length="0.05" radius="0.0125"/>
      </geometry>
    </collision>
  </link>
  <joint name="f1_dof3_joint" type="revolute">
    <parent link="f1_dof2_link"/>
    <child link="f1_dof3_link"/>
    <origin rpy="0 0 0" xyz="0.0384 0 0"/>
    <axis xyz="0 0 1"/>
    <limit effort="100" lower="-0.227000000882" upper="1.6179999956" velocity="100"/>
    <dynamics damping="0.002" friction="0.08"/>
  </joint>
  <link name="f1_dof3_link">
    <inertial>
      <origin xyz=" 0.01 0 0 "/>
      <inertia ixx="9.79166666667e-07" ixy="0" ixz="0" iyy="8.02916666667e-07" iyz="0" izz="8.02916666667e-07"/>
      <mass value="0.0094"/>
    </inertial>
    <visual>
      <origin rpy="0 0 1.57079632679" xyz="0.016 -0.0098 0.012"/>
      <!-- DONE -->
      <material name="WAMGrey">
        <color rgba="0.9 0.9 0.9 1.0"/>
      </material>
      <geometry>
        <mesh filename="package://allegro_hand_description/meshes/allegro_fingerdof0.dae"/>
      </geometry>
    </visual>
    <collision>
      <origin rpy="0 0 1.57079632679" xyz="0.016 -0.0098 0.012"/>
      <!-- DONE -->
      <geometry>
        <mesh filename="package://allegro_hand_description/meshes/allegro_fingerdof0.dae"/>
      </geometry>
    </collision>
  </link>
  <joint name="f1_dof4_joint" type="fixed">
    <parent link="f1_dof3_link"/>
    <child link="f1_dof4_link"/>
    <origin rpy="0 0 0" xyz="0.016 0 0"/>
  </joint>
  <link name="f1_dof4_link">
    <inertial>
      <origin xyz=" 0.01 0 0 "/>
      <inertia ixx="1.17333333333e-06" ixy="0" ixz="0" iyy="1.17333333333e-06" iyz="0" izz="1.17333333333e-06"/>
      <mass value="0.0176"/>
    </inertial>
    <visual>
      <origin rpy="0 0 -1.57079632679" xyz="0 0.012 0.012"/>
      <!-- DONE -->
      <material name="WAMGrey">
        <color rgba="0.9 0.9 0.9 0.0"/>
      </material>
      <geometry>
        <mesh filename="package://allegro_hand_description/meshes/allegro_fingertip.dae"/>
      </geometry>
    </visual>
    <collision name="f1_dof4_link_collision">
      <origin rpy="0 0 -1.57079632679" xyz=" 0.01 0 0 "/>
      <geometry>
        <sphere radius="0.01"/>
      </geometry>
    </collision>
  </link>
  <joint name="f2_dof0_joint" type="revolute">
    <parent link="ahand_palm_link"/>
    <child link="f2_dof0_link"/>
    <origin rpy="0 0 0.0" xyz="0 0 0"/>
    <axis xyz="0 0 1"/>
    <limit effort="100" lower="-0.469999993522" upper="0.469999993522" velocity="100"/>
    <dynamics damping="0.002" friction="0.08"/>
  </joint>
  <link name="f2_dof0_link">
    <inertial>
      <origin xyz="0.00 0 0.01"/>
      <inertia ixx="9.39583333333e-07" ixy="0" ixz="0" iyy="1.14583333333e-06" iyz="0" izz="9.39583333333e-07"/>
      <mass value="0.011"/>
    </inertial>
    <visual>
      <origin rpy="1.57079632679 0.0 0.0 " xyz="-0.0098 -0.012 0.0"/>
      <!-- DONE, OK -->
      <material name="all">
        <color rgba="0.1 0.1 0.1 0.5"/>
      </material>
      <geometry>
        <mesh filename="package://allegro_hand_description/meshes/allegro_fingerdof0.dae"/>
      </geometry>
    </visual>
    <collision>
      <origin rpy="1.57079632679 0.0 0.0 " xyz="-0.0098 -0.012 0.0"/>
      <!-- DONE, OK -->
      <material name="all">
        <color rgba="0.1 0.1 0.1 0.5"/>
      </material>
      <geometry>
        <mesh filename="package://allegro_hand_description/meshes/allegro_fingerdof0.dae"/>
      </geometry>
    </collision>
  </link>
  <joint name="f2_dof1_joint" type="revolute">
    <parent link="f2_dof0_link"/>
    <child link="f2_dof1_link"/>
    <origin rpy="-1.57079632679 0 0" xyz="0 0 0.0164"/>
    <axis xyz="0 0 1"/>
    <limit effort="100" lower="-0.19600000376" upper="1.60999999972" velocity="100"/>
    <dynamics damping="0.002" friction="0.08"/>
  </joint>
  <link name="f2_dof1_link">
    <inertial>
      <origin xyz="0.  -0.027 0 "/>
      <inertia ixx="2.01246833333e-05" ixy="0" ixz="0" iyy="7.10416666667e-06" iyz="0" izz="2.01246833333e-05"/>
      <mass value="0.0682"/>
    </inertial>
    <visual>
      <material name="WAMGrey">
        <color rgba="0.9 0.9 0.9 1.0"/>
      </material>
      <origin rpy="0 0 0.0" xyz="-0.0098 -0.0638 0.012"/>
      <!-- DONE -->
      <geometry>
        <mesh filename="package://allegro_hand_description/meshes/allegro_fingerdof1.dae"/>
      </geometry>
    </visual>
    <collision>
      <origin rpy="1.57079632679 0 0.0" xyz=" 0.  -0.027 0  "/>
      <geometry>
        <cylinder length="0.035" radius="0.0125"/>
      </geometry>
    </collision>
  </link>
  <joint name="f2_dof2_joint" type="revolute">
    <parent link="f2_dof1_link"/>
    <child link="f2_dof2_link"/>
    <origin rpy="0 0 -1.57079632679" xyz="0.0 -0.054 0.0"/>
    <!-- DONE -->
    <axis xyz="0 0 1"/>
    <limit effort="100" lower="-0.174000006366" upper="1.70899999672" velocity="100"/>
    <dynamics damping="0.002" friction="0.08"/>
  </joint>
  <link name="f2_dof2_link">
    <inertial>
      <origin xyz=" 0.0192 0 0 "/>
      <inertia ixx="4.1875e-06" ixy="0" ixz="0" iyy="7.033526e-06" iyz="0" izz="7.033526e-06"/>
      <mass value="0.0402"/>
    </inertial>
    <visual>
      <origin rpy="3.14159265359 0 1.57079632679" xyz="-0.0098 -0.0098 -0.012"/>
      <!-- DONE -->
      <material name="WAMGrey">
        <color rgba="0.9 0.9 0.9 0.0"/>
      </material>
      <geometry>
        <mesh filename="package://allegro_hand_description/meshes/allegro_fingerdof2.dae"/>
      </geometry>
    </visual>
    <collision>
      <origin rpy="1.57079632679 0 1.57079632679" xyz=" 0.0192 0 0 "/>
      <geometry>
        <cylinder length="0.05" radius="0.0125"/>
      </geometry>
    </collision>
  </link>
  <joint name="f2_dof3_joint" type="revolute">
    <parent link="f2_dof2_link"/>
    <child link="f2_dof3_link"/>
    <origin rpy="0 0 0" xyz="0.0384 0 0"/>
    <axis xyz="0 0 1"/>
    <limit effort="100" lower="-0.227000000882" upper="1.6179999956" velocity="100"/>
    <dynamics damping="0.002" friction="0.08"/>
  </joint>
  <link name="f2_dof3_link">
    <inertial>
      <origin xyz=" 0.01 0 0 "/>
      <inertia ixx="9.79166666667e-07" ixy="0" ixz="0" iyy="8.02916666667e-07" iyz="0" izz="8.02916666667e-07"/>
      <mass value="0.0094"/>
    </inertial>
    <visual>
      <origin rpy="0 0 1.57079632679" xyz="0.016 -0.0098 0.012"/>
      <!-- DONE -->
      <material name="WAMGrey">
        <color rgba="0.9 0.9 0.9 1.0"/>
      </material>
      <geometry>
        <mesh filename="package://allegro_hand_description/meshes/allegro_fingerdof0.dae"/>
      </geometry>
    </visual>
    <collision>
      <origin rpy="0 0 1.57079632679" xyz="0.016 -0.0098 0.012"/>
      <!-- DONE -->
      <geometry>
        <mesh filename="package://allegro_hand_description/meshes/allegro_fingerdof0.dae"/>
      </geometry>
    </collision>
  </link>
  <joint name="f2_dof4_joint" type="fixed">
    <parent link="f2_dof3_link"/>
    <child link="f2_dof4_link"/>
    <origin rpy="0 0 0" xyz="0.016 0 0"/>
  </joint>
  <link name="f2_dof4_link">
    <inertial>
      <origin xyz=" 0.01 0 0 "/>
      <inertia ixx="1.17333333333e-06" ixy="0" ixz="0" iyy="1.17333333333e-06" iyz="0" izz="1.17333333333e-06"/>
      <mass value="0.0176"/>
    </inertial>
    <visual>
      <origin rpy="0 0 -1.57079632679" xyz="0 0.012 0.012"/>
      <!-- DONE -->
      <material name="WAMGrey">
        <color rgba="0.9 0.9 0.9 0.0"/>
      </material>
      <geometry>
        <mesh filename="package://allegro_hand_description/meshes/allegro_fingertip.dae"/>
      </geometry>
    </visual>
    <collision name="f2_dof4_link_collision">
      <origin rpy="0 0 -1.57079632679" xyz=" 0.01 0 0 "/>
      <geometry>
        <sphere radius="0.01"/>
      </geometry>
    </collision>
  </link>
  <joint name="f3_dof0_joint" type="revolute">
    <parent link="ahand_palm_link"/>
    <child link="f3_dof0_link"/>
    <origin rpy="-0.0873 0 -0.0" xyz="0 0.044981 -0.002298"/>
    <axis xyz="0 0 1"/>
    <limit effort="100" lower="-0.469999993522" upper="0.469999993522" velocity="100"/>
    <dynamics damping="0.002" friction="0.08"/>
  </joint>
  <link name="f3_dof0_link">
    <inertial>
      <origin xyz="0.00 0 0.01"/>
      <inertia ixx="9.39583333333e-07" ixy="0" ixz="0" iyy="1.14583333333e-06" iyz="0" izz="9.39583333333e-07"/>
      <mass value="0.011"/>
    </inertial>
    <visual>
      <origin rpy="1.57079632679 0.0 0.0 " xyz="-0.0098 -0.012 0.0"/>
      <!-- DONE, OK -->
      <material name="all">
        <color rgba="0.1 0.1 0.1 0.5"/>
      </material>
      <geometry>
        <mesh filename="package://allegro_hand_description/meshes/allegro_fingerdof0.dae"/>
      </geometry>
    </visual>
    <collision>
      <origin rpy="1.57079632679 0.0 0.0 " xyz="-0.0098 -0.012 0.0"/>
      <!-- DONE, OK -->
      <material name="all">
        <color rgba="0.1 0.1 0.1 0.5"/>
      </material>
      <geometry>
        <mesh filename="package://allegro_hand_description/meshes/allegro_fingerdof0.dae"/>
      </geometry>
    </collision>
  </link>
  <joint name="f3_dof1_joint" type="revolute">
    <parent link="f3_dof0_link"/>
    <child link="f3_dof1_link"/>
    <origin rpy="-1.57079632679 0 0" xyz="0 0 0.0164"/>
    <axis xyz="0 0 1"/>
    <limit effort="100" lower="-0.19600000376" upper="1.60999999972" velocity="100"/>
    <dynamics damping="0.002" friction="0.08"/>
  </joint>
  <link name="f3_dof1_link">
    <inertial>
      <origin xyz="0.  -0.027 0 "/>
      <inertia ixx="2.01246833333e-05" ixy="0" ixz="0" iyy="7.10416666667e-06" iyz="0" izz="2.01246833333e-05"/>
      <mass value="0.0682"/>
    </inertial>
    <visual>
      <material name="WAMGrey">
        <color rgba="0.9 0.9 0.9 1.0"/>
      </material>
      <origin rpy="0 0 0.0" xyz="-0.0098 -0.0638 0.012"/>
      <!-- DONE -->
      <geometry>
        <mesh filename="package://allegro_hand_description/meshes/allegro_fingerdof1.dae"/>
      </geometry>
    </visual>
    <collision>
      <origin rpy="1.57079632679 0 0.0" xyz=" 0.  -0.027 0  "/>
      <geometry>
        <cylinder length="0.035" radius="0.0125"/>
      </geometry>
    </collision>
  </link>
  <joint name="f3_dof2_joint" type="revolute">
    <parent link="f3_dof1_link"/>
    <child link="f3_dof2_link"/>
    <origin rpy="0 0 -1.57079632679" xyz="0.0 -0.054 0.0"/>
    <!-- DONE -->
    <axis xyz="0 0 1"/>
    <limit effort="100" lower="-0.174000006366" upper="1.70899999672" velocity="100"/>
    <dynamics damping="0.002" friction="0.08"/>
  </joint>
  <link name="f3_dof2_link">
    <inertial>
      <origin xyz=" 0.0192 0 0 "/>
      <inertia ixx="4.1875e-06" ixy="0" ixz="0" iyy="7.033526e-06" iyz="0" izz="7.033526e-06"/>
      <mass value="0.0402"/>
    </inertial>
    <visual>
      <origin rpy="3.14159265359 0 1.57079632679" xyz="-0.0098 -0.0098 -0.012"/>
      <!-- DONE -->
      <material name="WAMGrey">
        <color rgba="0.9 0.9 0.9 0.0"/>
      </material>
      <geometry>
        <mesh filename="package://allegro_hand_description/meshes/allegro_fingerdof2.dae"/>
      </geometry>
    </visual>
    <collision>
      <origin rpy="1.57079632679 0 1.57079632679" xyz=" 0.0192 0 0 "/>
      <geometry>
        <cylinder length="0.05" radius="0.0125"/>
      </geometry>
    </collision>
  </link>
  <joint name="f3_dof3_joint" type="revolute">
    <parent link="f3_dof2_link"/>
    <child link="f3_dof3_link"/>
    <origin rpy="0 0 0" xyz="0.0384 0 0"/>
    <axis xyz="0 0 1"/>
    <limit effort="100" lower="-0.227000000882" upper="1.6179999956" velocity="100"/>
    <dynamics damping="0.002" friction="0.08"/>
  </joint>
  <link name="f3_dof3_link">
    <inertial>
      <origin xyz=" 0.01 0 0 "/>
      <inertia ixx="9.79166666667e-07" ixy="0" ixz="0" iyy="8.02916666667e-07" iyz="0" izz="8.02916666667e-07"/>
      <mass value="0.0094"/>
    </inertial>
    <visual>
      <origin rpy="0 0 1.57079632679" xyz="0.016 -0.0098 0.012"/>
      <!-- DONE -->
      <material name="WAMGrey">
        <color rgba="0.9 0.9 0.9 1.0"/>
      </material>
      <geometry>
        <mesh filename="package://allegro_hand_description/meshes/allegro_fingerdof0.dae"/>
      </geometry>
    </visual>
    <collision>
      <origin rpy="0 0 1.57079632679" xyz="0.016 -0.0098 0.012"/>
      <!-- DONE -->
      <geometry>
        <mesh filename="package://allegro_hand_description/meshes/allegro_fingerdof0.dae"/>
      </geometry>
    </collision>
  </link>
  <joint name="f3_dof4_joint" type="fixed">
    <parent link="f3_dof3_link"/>
    <child link="f3_dof4_link"/>
    <origin rpy="0 0 0" xyz="0.016 0 0"/>
  </joint>
  <link name="f3_dof4_link">
    <inertial>
      <origin xyz=" 0.01 0 0 "/>
      <inertia ixx="1.17333333333e-06" ixy="0" ixz="0" iyy="1.17333333333e-06" iyz="0" izz="1.17333333333e-06"/>
      <mass value="0.0176"/>
    </inertial>
    <visual>
      <origin rpy="0 0 -1.57079632679" xyz="0 0.012 0.012"/>
      <!-- DONE -->
      <material name="WAMGrey">
        <color rgba="0.9 0.9 0.9 0.0"/>
      </material>
      <geometry>
        <mesh filename="package://allegro_hand_description/meshes/allegro_fingertip.dae"/>
      </geometry>
    </visual>
    <collision name="f3_dof4_link_collision">
      <origin rpy="0 0 -1.57079632679" xyz=" 0.01 0 0 "/>
      <geometry>
        <sphere radius="0.01"/>
      </geometry>
    </collision>
  </link>
  <joint name="thumb_dof0_joint" type="revolute">
    <parent link="ahand_palm_link"/>
    <child link="thumb_dof0_link"/>
    <origin rpy="-3.0543 0 0.0" xyz="-0.0182 -0.0168753 -0.07308"/>
    <axis xyz="0 0 1"/>
    <limit effort="100" lower="-1.0" upper="85.0" velocity="100"/>
    <!-- new version, it still needs to be negative ... -->
    <dynamics damping="0.002" friction="0.08"/>
  </joint>
  <link name="thumb_dof0_link">
    <inertial>
      <origin xyz="-0.0025 0.02 -0.01 "/>
      <inertia ixx="2.66666666667e-08" ixy="0" ixz="0" iyy="1.66666666667e-08" iyz="0" izz="1.66666666667e-08"/>
      <mass value="0.0001"/>
    </inertial>
    <visual>
      <origin rpy="-1.57079632679 0.0 3.14159265359 " xyz="0.025 -0.0088 0.010"/>
      <!-- DONE -->
      <material name="all">
        <color rgba="0.1 0.1 0.1 0.5"/>
      </material>
      <geometry>
        <mesh filename="package://allegro_hand_description/meshes/allegro_thumbdof0.dae"/>
      </geometry>
    </visual>
    <!--collision>
        		<origin xyz="0.025 -0.0088 0.010" rpy="${-PI/2} ${0} ${PI} "/> 
        		<geometry>
          			<mesh filename="${models_path}/shapes/allegro_thumbdof0.dae"/>
        		</geometry>
      		</collision-->
  </link>
  <joint name="thumb_dof1_joint" type="revolute">
    <parent link="thumb_dof0_link"/>
    <child link="thumb_dof1_link"/>
    <origin rpy="-1.57079632679 0.0 0.0" xyz="0 0.0375 -0.0034"/>
    <!-- DONE -->
    <axis xyz="0 0 1"/>
    <limit effort="100" lower="-66.0" upper="6.0" velocity="100"/>
    <dynamics damping="0.002" friction="0.08"/>
  </joint>
  <link name="thumb_dof1_link">
    <inertial>
      <origin xyz="0.00 0.00 0.015 "/>
      <inertia ixx="6.66666666667e-09" ixy="0" ixz="0" iyy="6.66666666667e-09" iyz="0" izz="6.66666666667e-09"/>
      <mass value="0.0001"/>
    </inertial>
    <visual>
      <material name="WAMGrey">
        <color rgba="0.9 0.9 0.9 0.0"/>
      </material>
      <origin rpy="1.57079632679 0.0 1.57079632679" xyz="0.012 -0.0098 0"/>
      <!-- DONE -->
      <geometry>
        <mesh filename="package://allegro_hand_description/meshes/allegro_fingerdof0.dae"/>
      </geometry>
    </visual>
    <!--collision>
	       		<origin xyz="0.012 -0.0098 0" rpy="${PI/2} ${0} ${PI/2}" />
        		<geometry>
        			<mesh filename="${models_path}/shapes/allegro_fingerdof0.dae"/>
        		</geometry>
      		</collision> -->
  </link>
  <joint name="thumb_dof2_joint" type="revolute">
    <parent link="thumb_dof1_link"/>
    <child link="thumb_dof2_link"/>
    <origin rpy="-1.57079632679 0 1.57079632679" xyz="0 0 0.0177"/>
    <!-- DONE -->
    <axis xyz="0 0 1"/>
    <limit effort="100" lower="-10.8" upper="94.0" velocity="100"/>
    <dynamics damping="0.002" friction="0.08"/>
  </joint>
  <link name="thumb_dof2_link">
    <inertial>
      <origin xyz="0.00 -0.028 0.00 "/>
      <inertia ixx="2.41666666667e-08" ixy="0" ixz="0" iyy="6.66666666667e-09" iyz="0" izz="2.41666666667e-08"/>
      <mass value="0.0001"/>
    </inertial>
    <visual>
      <origin xyz="-0.0098 -0.063 0.012"/>
      <material name="WAMGrey">
        <color rgba="0.9 0.9 0.9 0.0"/>
      </material>
      <geometry>
        <mesh filename="package://allegro_hand_description/meshes/allegro_fingerdof1.dae"/>
      </geometry>
    </visual>
    <!--<collision>
			<origin xyz="-0.0098 -0.063 0.012" />
        		<geometry>
          			<mesh filename="${models_path}/shapes/allegro_fingerdof1.dae"/>
        		</geometry>
      		</collision> -->
  </link>
  <joint name="thumb_dof3_joint" type="revolute">
    <parent link="thumb_dof2_link"/>
    <child link="thumb_dof3_link"/>
    <origin rpy="0 0 -1.57079632679" xyz="0 -0.0514 0"/>
    <!-- DONE -->
    <axis xyz="0 0 1"/>
    <limit effort="100" lower="0.0" upper="98.0" velocity="100"/>
    <dynamics damping="0.002" friction="0.08"/>
  </joint>
  <link name="thumb_dof3_link">
    <inertial>
      <origin xyz="0.025 0.0 0.0 "/>
      <inertia ixx="6.66666666667e-09" ixy="0" ixz="0" iyy="1.66666666667e-08" iyz="0" izz="1.66666666667e-08"/>
      <mass value="0.0001"/>
    </inertial>
    <visual>
      <origin rpy="0 0 -1.57079632679" xyz="-0.0078 0.0098 0.012"/>
      <!-- DONE -->
      <material name="WAMGrey">
        <color rgba="0.9 0.9 0.9 0.0"/>
      </material>
      <geometry>
        <mesh filename="package://allegro_hand_description/meshes/allegro_thumbdof3.dae"/>
      </geometry>
    </visual>
  </link>
  <joint name="thumb_dof4_joint" type="fixed">
    <parent link="thumb_dof3_link"/>
    <child link="thumb_dof4_link"/>
    <origin rpy="0 0 0" xyz="0.046 0 0"/>
    <!-- DONE -->
  </joint>
  <link name="thumb_dof4_link">
    <inertial>
      <origin xyz="0.01 0.0 0.0 "/>
      <inertia ixx="6.66666666667e-09" ixy="0" ixz="0" iyy="6.66666666667e-09" iyz="0" izz="6.66666666667e-09"/>
      <mass value="0.0001"/>
    </inertial>
    <visual>
      <origin rpy="0 0 -1.57079632679" xyz="0 0.012 0.012"/>
      <!-- DONE -->
      <material name="WAMGrey">
        <color rgba="0.9 0.9 0.9 0.0"/>
      </material>
      <geometry>
        <mesh filename="package://allegro_hand_description/meshes/allegro_fingertip.dae"/>
      </geometry>
    </visual>
    <!--collision>
   			<origin xyz="0 0.012 0.012" rpy="0 0 ${-PI/2}"/> 
    			<geometry>
      			<mesh filename="${models_path}/shapes/allegro_fingertip.dae"/>
   			</geometry>
  		</collision> -->
  </link>
  <gazebo reference="ahand_palm_link">
    <mu1>0.05</mu1>
    <mu2>0.05</mu2>
    <kp>400000</kp>
  </gazebo>
  <gazebo reference="f1_dof0_joint">
    <provideFeedback>true</provideFeedback>
    <implicitSpringDamper>true</implicitSpringDamper>
  </gazebo>
  <gazebo reference="f1_dof1_link">
    <mu1>0.05</mu1>
    <mu2>0.05</mu2>
    <kp>400000</kp>
  </gazebo>
  <gazebo reference="f1_dof1_joint">
    <provideFeedback>true</provideFeedback>
    <implicitSpringDamper>true</implicitSpringDamper>
  </gazebo>
  <gazebo reference="f1_dof1_link">
    <mu1>0.05</mu1>
    <mu2>0.05</mu2>
    <kp>400000</kp>
  </gazebo>
  <gazebo reference="f1_dof2_joint">
    <provideFeedback>true</provideFeedback>
    <implicitSpringDamper>true</implicitSpringDamper>
  </gazebo>
  <gazebo reference="f1_dof1_link">
    <mu1>0.05</mu1>
    <mu2>0.05</mu2>
    <kp>400000</kp>
  </gazebo>
  <gazebo reference="f1_dof3_joint">
    <provideFeedback>true</provideFeedback>
    <implicitSpringDamper>true</implicitSpringDamper>
  </gazebo>
  <gazebo reference="f1_dof1_link">
    <mu1>0.05</mu1>
    <mu2>0.05</mu2>
    <kp>400000</kp>
  </gazebo>
  <gazebo reference="f2_dof0_joint">
    <provideFeedback>true</provideFeedback>
    <implicitSpringDamper>true</implicitSpringDamper>
  </gazebo>
  <gazebo reference="f2_dof1_link">
    <mu1>0.05</mu1>
    <mu2>0.05</mu2>
    <kp>400000</kp>
  </gazebo>
  <gazebo reference="f2_dof1_joint">
    <provideFeedback>true</provideFeedback>
    <implicitSpringDamper>true</implicitSpringDamper>
  </gazebo>
  <gazebo reference="f2_dof1_link">
    <mu1>0.05</mu1>
    <mu2>0.05</mu2>
    <kp>400000</kp>
  </gazebo>
  <gazebo reference="f2_dof2_joint">
    <provideFeedback>true</provideFeedback>
    <implicitSpringDamper>true</implicitSpringDamper>
  </gazebo>
  <gazebo reference="f2_dof1_link">
    <mu1>0.05</mu1>
    <mu2>0.05</mu2>
    <kp>400000</kp>
  </gazebo>
  <gazebo reference="f2_dof3_joint">
    <provideFeedback>true</provideFeedback>
    <implicitSpringDamper>true</implicitSpringDamper>
  </gazebo>
  <gazebo reference="f2_dof1_link">
    <mu1>0.05</mu1>
    <mu2>0.05</mu2>
    <kp>400000</kp>
  </gazebo>
  <gazebo reference="f3_dof0_joint">
    <provideFeedback>true</provideFeedback>
    <implicitSpringDamper>true</implicitSpringDamper>
  </gazebo>
  <gazebo reference="f3_dof1_link">
    <mu1>0.05</mu1>
    <mu2>0.05</mu2>
    <kp>400000</kp>
  </gazebo>
  <gazebo reference="f3_dof1_joint">
    <provideFeedback>true</provideFeedback>
    <implicitSpringDamper>true</implicitSpringDamper>
  </gazebo>
  <gazebo reference="f3_dof1_link">
    <mu1>0.05</mu1>
    <mu2>0.05</mu2>
    <kp>400000</kp>
  </gazebo>
  <gazebo reference="f3_dof2_joint">
    <provideFeedback>true</provideFeedback>
    <implicitSpringDamper>true</implicitSpringDamper>
  </gazebo>
  <gazebo reference="f3_dof1_link">
    <mu1>0.05</mu1>
    <mu2>0.05</mu2>
    <kp>400000</kp>
  </gazebo>
  <gazebo reference="f3_dof3_joint">
    <provideFeedback>true</provideFeedback>
    <implicitSpringDamper>true</implicitSpringDamper>
  </gazebo>
  <gazebo reference="f3_dof1_link">
    <mu1>0.05</mu1>
    <mu2>0.05</mu2>
    <kp>400000</kp>
  </gazebo>
  <gazebo reference="thumb_dof0_joint">
    <provideFeedback>true</provideFeedback>
    <implicitSpringDamper>true</implicitSpringDamper>
  </gazebo>
  <gazebo reference="thumb_dof1_link">
    <mu1>0.05</mu1>
    <mu2>0.05</mu2>
    <kp>400000</kp>
  </gazebo>
  <gazebo reference="thumb_dof1_joint">
    <provideFeedback>true</provideFeedback>
    <implicitSpringDamper>true</implicitSpringDamper>
  </gazebo>
  <gazebo reference="thumb_dof1_link">
    <mu1>0.05</mu1>
    <mu2>0.05</mu2>
    <kp>400000</kp>
  </gazebo>
  <gazebo reference="thumb_dof2_joint">
    <provideFeedback>true</provideFeedback>
    <implicitSpringDamper>true</implicitSpringDamper>
  </gazebo>
  <gazebo reference="thumb_dof1_link">
    <mu1>0.05</mu1>
    <mu2>0.05</mu2>
    <kp>400000</kp>
  </gazebo>
  <gazebo reference="thumb_dof3_joint">
    <provideFeedback>true</provideFeedback>
    <implicitSpringDamper>true</implicitSpringDamper>
  </gazebo>
  <gazebo reference="thumb_dof1_link">
    <mu1>0.05</mu1>
    <mu2>0.05</mu2>
    <kp>400000</kp>
  </gazebo>
  <transmission name="f1_dof0_trans">
    <type>transmission_interface/SimpleTransmission</type>
    <joint name="f1_dof0_joint">
      <hardwareInterface>EffortJointInterface</hardwareInterface>
    </joint>
    <actuator name="f1_dof0_motor">
      <hardwareInterface>EffortJointInterface</hardwareInterface>
      <mechanicalReduction>1</mechanicalReduction>
    </actuator>
  </transmission>
  <transmission name="f1_dof1_trans">
    <type>transmission_interface/SimpleTransmission</type>
    <joint name="f1_dof1_joint">
      <hardwareInterface>EffortJointInterface</hardwareInterface>
    </joint>
    <actuator name="f1_dof1_motor">
      <hardwareInterface>EffortJointInterface</hardwareInterface>
      <mechanicalReduction>1</mechanicalReduction>
    </actuator>
  </transmission>
  <transmission name="f1_dof2_trans">
    <type>transmission_interface/SimpleTransmission</type>
    <joint name="f1_dof2_joint">
      <hardwareInterface>EffortJointInterface</hardwareInterface>
    </joint>
    <actuator name="f1_dof2_motor">
      <hardwareInterface>EffortJointInterface</hardwareInterface>
      <mechanicalReduction>1</mechanicalReduction>
    </actuator>
  </transmission>
  <transmission name="f1_dof3_trans">
    <type>transmission_interface/SimpleTransmission</type>
    <joint name="f1_dof3_joint">
      <hardwareInterface>EffortJointInterface</hardwareInterface>
    </joint>
    <actuator name="f1_dof3_motor">
      <hardwareInterface>EffortJointInterface</hardwareInterface>
      <mechanicalReduction>1</mechanicalReduction>
    </actuator>
  </transmission>
  <transmission name="f2_dof0_trans">
    <type>transmission_interface/SimpleTransmission</type>
    <joint name="f2_dof0_joint">
      <hardwareInterface>EffortJointInterface</hardwareInterface>
    </joint>
    <actuator name="f2_dof0_motor">
      <hardwareInterface>EffortJointInterface</hardwareInterface>
      <mechanicalReduction>1</mechanicalReduction>
    </actuator>
  </transmission>
  <transmission name="f2_dof1_trans">
    <type>transmission_interface/SimpleTransmission</type>
    <joint name="f2_dof1_joint">
      <hardwareInterface>EffortJointInterface</hardwareInterface>
    </joint>
    <actuator name="f2_dof1_motor">
      <hardwareInterface>EffortJointInterface</hardwareInterface>
      <mechanicalReduction>1</mechanicalReduction>
    </actuator>
  </transmission>
  <transmission name="f2_dof2_trans">
    <type>transmission_interface/SimpleTransmission</type>
    <joint name="f2_dof2_joint">
      <hardwareInterface>EffortJointInterface</hardwareInterface>
    </joint>
    <actuator name="f2_dof2_motor">
      <hardwareInterface>EffortJointInterface</hardwareInterface>
      <mechanicalReduction>1</mechanicalReduction>
    </actuator>
  </transmission>
  <transmission name="f2_dof3_trans">
    <type>transmission_interface/SimpleTransmission</type>
    <joint name="f2_dof3_joint">
      <hardwareInterface>EffortJointInterface</hardwareInterface>
    </joint>
    <actuator name="f2_dof3_motor">
      <hardwareInterface>EffortJointInterface</hardwareInterface>
      <mechanicalReduction>1</mechanicalReduction>
    </actuator>
  </transmission>
  <transmission name="f3_dof0_trans">
    <type>transmission_interface/SimpleTransmission</type>
    <joint name="f3_dof0_joint">
      <hardwareInterface>EffortJointInterface</hardwareInterface>
    </joint>
    <actuator name="f3_dof0_motor">
      <hardwareInterface>EffortJointInterface</hardwareInterface>
      <mechanicalReduction>1</mechanicalReduction>
    </actuator>
  </transmission>
  <transmission name="f3_dof1_trans">
    <type>transmission_interface/SimpleTransmission</type>
    <joint name="f3_dof1_joint">
      <hardwareInterface>EffortJointInterface</hardwareInterface>
    </joint>
    <actuator name="f3_dof1_motor">
      <hardwareInterface>EffortJointInterface</hardwareInterface>
      <mechanicalReduction>1</mechanicalReduction>
    </actuator>
  </transmission>
  <transmission name="f3_dof2_trans">
    <type>transmission_interface/SimpleTransmission</type>
    <joint name="f3_dof2_joint">
      <hardwareInterface>EffortJointInterface</hardwareInterface>
    </joint>
    <actuator name="f3_dof2_motor">
      <hardwareInterface>EffortJointInterface</hardwareInterface>
      <mechanicalReduction>1</mechanicalReduction>
    </actuator>
  </transmission>
  <transmission name="f3_dof3_trans">
    <type>transmission_interface/SimpleTransmission</type>
    <joint name="f3_dof3_joint">
      <hardwareInterface>EffortJointInterface</hardwareInterface>
    </joint>
    <actuator name="f3_dof3_motor">
      <hardwareInterface>EffortJointInterface</hardwareInterface>
      <mechanicalReduction>1</mechanicalReduction>
    </actuator>
  </transmission>
  <transmission name="thumb_dof0_trans">
    <type>transmission_interface/SimpleTransmission</type>
    <joint name="thumb_dof0_joint">
      <hardwareInterface>EffortJointInterface</hardwareInterface>
    </joint>
    <actuator name="thumb_dof0_motor">
      <hardwareInterface>EffortJointInterface</hardwareInterface>
      <mechanicalReduction>1</mechanicalReduction>
    </actuator>
  </transmission>
  <transmission name="thumb_dof1_trans">
    <type>transmission_interface/SimpleTransmission</type>
    <joint name="thumb_dof1_joint">
      <hardwareInterface>EffortJointInterface</hardwareInterface>
    </joint>
    <actuator name="thumb_dof1_motor">
      <hardwareInterface>EffortJointInterface</hardwareInterface>
      <mechanicalReduction>1</mechanicalReduction>
    </actuator>
  </transmission>
  <transmission name="thumb_dof2_trans">
    <type>transmission_interface/SimpleTransmission</type>
    <joint name="thumb_dof2_joint">
      <hardwareInterface>EffortJointInterface</hardwareInterface>
    </joint>
    <actuator name="thumb_dof2_motor">
      <hardwareInterface>EffortJointInterface</hardwareInterface>
      <mechanicalReduction>1</mechanicalReduction>
    </actuator>
  </transmission>
  <transmission name="thumb_dof3_trans">
    <type>transmission_interface/SimpleTransmission</type>
    <joint name="thumb_dof3_joint">
      <hardwareInterface>EffortJointInterface</hardwareInterface>
    </joint>
    <actuator name="thumb_dof3_motor">
      <hardwareInterface>EffortJointInterface</hardwareInterface>
      <mechanicalReduction>1</mechanicalReduction>
    </actuator>
  </transmission>
</robot>

